<?xml version="1.0" ?>
<!-- =================================================================================== -->
<!-- |    This document was autogenerated by xacro from genesis/assets/urdf/csento/csento-4ac_description/urdf/csento-4ac.xacro | -->
<!-- |    EDITING THIS FILE BY HAND IS NOT RECOMMENDED                                 | -->
<!-- =================================================================================== -->
<robot name="csento-4ac">
  <material name="silver">
    <color rgba="0.700 0.700 0.700 1.000"/>
  </material>
  <transmission name="left_hip_joint_tran">
    <type>transmission_interface/SimpleTransmission</type>
    <joint name="left_hip_joint">
      <hardwareInterface>hardware_interface/EffortJointInterface</hardwareInterface>
    </joint>
    <actuator name="left_hip_joint_actr">
      <hardwareInterface>hardware_interface/EffortJointInterface</hardwareInterface>
      <mechanicalReduction>1</mechanicalReduction>
    </actuator>
  </transmission>
  <transmission name="right_hip_joint_tran">
    <type>transmission_interface/SimpleTransmission</type>
    <joint name="right_hip_joint">
      <hardwareInterface>hardware_interface/EffortJointInterface</hardwareInterface>
    </joint>
    <actuator name="right_hip_joint_actr">
      <hardwareInterface>hardware_interface/EffortJointInterface</hardwareInterface>
      <mechanicalReduction>1</mechanicalReduction>
    </actuator>
  </transmission>
  <transmission name="right_wheel_joint_tran">
    <type>transmission_interface/SimpleTransmission</type>
    <joint name="right_wheel_joint">
      <hardwareInterface>hardware_interface/EffortJointInterface</hardwareInterface>
    </joint>
    <actuator name="right_wheel_joint_actr">
      <hardwareInterface>hardware_interface/EffortJointInterface</hardwareInterface>
      <mechanicalReduction>1</mechanicalReduction>
    </actuator>
  </transmission>
  <transmission name="left_wheel_joint_tran">
    <type>transmission_interface/SimpleTransmission</type>
    <joint name="left_wheel_joint">
      <hardwareInterface>hardware_interface/EffortJointInterface</hardwareInterface>
    </joint>
    <actuator name="left_wheel_joint_actr">
      <hardwareInterface>hardware_interface/EffortJointInterface</hardwareInterface>
      <mechanicalReduction>1</mechanicalReduction>
    </actuator>
  </transmission>
  <transmission name="right_knee_joint_tran">
    <type>transmission_interface/SimpleTransmission</type>
    <joint name="right_knee_joint">
      <hardwareInterface>hardware_interface/EffortJointInterface</hardwareInterface>
    </joint>
    <actuator name="right_knee_joint_actr">
      <hardwareInterface>hardware_interface/EffortJointInterface</hardwareInterface>
      <mechanicalReduction>1</mechanicalReduction>
    </actuator>
  </transmission>
  <transmission name="left_knee_joint_tran">
    <type>transmission_interface/SimpleTransmission</type>
    <joint name="left_knee_joint">
      <hardwareInterface>hardware_interface/EffortJointInterface</hardwareInterface>
    </joint>
    <actuator name="left_knee_joint_actr">
      <hardwareInterface>hardware_interface/EffortJointInterface</hardwareInterface>
      <mechanicalReduction>1</mechanicalReduction>
    </actuator>
  </transmission>
  <gazebo>
    <plugin filename="libgazebo_ros_control.so" name="control"/>
  </gazebo>
  <gazebo reference="base_link">
    <material>Gazebo/Silver</material>
    <mu1>0.2</mu1>
    <mu2>0.2</mu2>
    <self_collide>true</self_collide>
    <gravity>true</gravity>
  </gazebo>
  <gazebo reference="left_leg_link_1">
    <material>Gazebo/Silver</material>
    <mu1>0.2</mu1>
    <mu2>0.2</mu2>
    <self_collide>true</self_collide>
  </gazebo>
  <gazebo reference="right_leg_link_1">
    <material>Gazebo/Silver</material>
    <mu1>0.2</mu1>
    <mu2>0.2</mu2>
    <self_collide>true</self_collide>
  </gazebo>
  <gazebo reference="right_wheel_1">
    <material>Gazebo/Silver</material>
    <mu1>0.2</mu1>
    <mu2>0.2</mu2>
    <self_collide>true</self_collide>
  </gazebo>
  <gazebo reference="left_wheel_1">
    <material>Gazebo/Silver</material>
    <mu1>0.2</mu1>
    <mu2>0.2</mu2>
    <self_collide>true</self_collide>
  </gazebo>
  <gazebo reference="right_hip_main_link_1">
    <material>Gazebo/Silver</material>
    <mu1>0.2</mu1>
    <mu2>0.2</mu2>
    <self_collide>true</self_collide>
  </gazebo>
  <gazebo reference="left_hip_main_link_1">
    <material>Gazebo/Silver</material>
    <mu1>0.2</mu1>
    <mu2>0.2</mu2>
    <self_collide>true</self_collide>
  </gazebo>
  <link name="base_link">
    <inertial>
      <origin rpy="0 0 0" xyz="1.2221840620011837e-15 -1.344402468201302e-15 0.07499422815852935"/>
      <mass value="5.048349302415931"/>
      <inertia ixx="0.022851" ixy="0.0" ixz="0.0" iyy="0.021218" iyz="-0.001749" izz="0.027446"/>
    </inertial>
    <visual>
      <origin rpy="0 0 0" xyz="0 0 0"/>
      <geometry>
        <mesh filename="../meshes/base_link.stl" scale="0.001 0.001 0.001"/>
      </geometry>
      <material name="silver"/>
    </visual>
    <collision>
      <origin rpy="0 0 0" xyz="0 0 0"/>
      <geometry>
        <mesh filename="../meshes/base_link.stl" scale="0.001 0.001 0.001"/>
      </geometry>
    </collision>
  </link>
  <link name="left_leg_link_1">
    <inertial>
      <origin rpy="0 0 0" xyz="0.005000000000001087 3.4123934257479503e-06 -0.04364139310878208"/>
      <mass value="0.049572840146082736"/>
      <inertia ixx="0.000134" ixy="0.0" ixz="0.0" iyy="0.000131" iyz="0.0" izz="3e-06"/>
    </inertial>
    <visual>
      <origin rpy="0 0 0" xyz="-0.105 -0.0 0.109"/>
      <geometry>
        <mesh filename="../meshes/left_leg_link_1.stl" scale="0.001 0.001 0.001"/>
      </geometry>
      <material name="silver"/>
    </visual>
    <collision>
      <origin rpy="0 0 0" xyz="-0.105 -0.0 0.109"/>
      <geometry>
        <mesh filename="../meshes/left_leg_link_1.stl" scale="0.001 0.001 0.001"/>
      </geometry>
    </collision>
  </link>
  <link name="right_leg_link_1">
    <inertial>
      <origin rpy="0 0 0" xyz="-0.004999999999998797 3.412393425712423e-06 -0.04364139310878214"/>
      <mass value="0.049572840146082736"/>
      <inertia ixx="0.000134" ixy="-0.0" ixz="-0.0" iyy="0.000131" iyz="0.0" izz="3e-06"/>
    </inertial>
    <visual>
      <origin rpy="0 0 0" xyz="0.105 0.0 0.109"/>
      <geometry>
        <mesh filename="../meshes/right_leg_link_1.stl" scale="0.001 0.001 0.001"/>
      </geometry>
      <material name="silver"/>
    </visual>
    <collision>
      <origin rpy="0 0 0" xyz="0.105 0.0 0.109"/>
      <geometry>
        <mesh filename="../meshes/right_leg_link_1.stl" scale="0.001 0.001 0.001"/>
      </geometry>
    </collision>
  </link>
  <link name="right_wheel_1">
    <inertial>
      <origin rpy="0 0 0" xyz="-0.012378168968434841 -1.0395457435431125e-05 -1.592358780944103e-08"/>
      <mass value="0.32978061044955914"/>
      <inertia ixx="0.000671" ixy="-0.0" ixz="-0.0" iyy="0.000352" iyz="-0.0" izz="0.000351"/>
    </inertial>
    <visual>
      <origin rpy="0 0 0" xyz="0.115 -7e-06 0.242"/>
      <geometry>
        <mesh filename="../meshes/right_wheel_1.stl" scale="0.001 0.001 0.001"/>
      </geometry>
      <material name="silver"/>
    </visual>
    <collision>
      <origin rpy="0 0 0" xyz="0.115 -7e-06 0.242"/>
      <geometry>
        <mesh filename="../meshes/right_wheel_1.stl" scale="0.001 0.001 0.001"/>
      </geometry>
    </collision>
  </link>
  <link name="left_wheel_1">
    <inertial>
      <origin rpy="0 0 0" xyz="0.012378168809641668 1.0528252256866493e-05 -1.4934656511478295e-08"/>
      <mass value="0.3297801928414847"/>
      <inertia ixx="0.000671" ixy="-0.0" ixz="0.0" iyy="0.000352" iyz="0.0" izz="0.000351"/>
    </inertial>
    <visual>
      <origin rpy="0 0 0" xyz="-0.115 -7e-06 0.242"/>
      <geometry>
        <mesh filename="../meshes/left_wheel_1.stl" scale="0.001 0.001 0.001"/>
      </geometry>
      <material name="silver"/>
    </visual>
    <collision>
      <origin rpy="0 0 0" xyz="-0.115 -7e-06 0.242"/>
      <geometry>
        <mesh filename="../meshes/left_wheel_1.stl" scale="0.001 0.001 0.001"/>
      </geometry>
    </collision>
  </link>
  <link name="right_hip_main_link_1">
    <inertial>
      <origin rpy="0 0 0" xyz="-0.004999999999998769 2.9738073348717364e-05 -0.05455435422776721"/>
      <mass value="0.06745093371390704"/>
      <inertia ixx="0.00017" ixy="-0.0" ixz="0.0" iyy="0.000162" iyz="-0.0" izz="9e-06"/>
    </inertial>
    <visual>
      <origin rpy="0 0 0" xyz="0.095 -0.0 -0.04"/>
      <geometry>
        <mesh filename="../meshes/right_hip_main_link_1.stl" scale="0.001 0.001 0.001"/>
      </geometry>
      <material name="silver"/>
    </visual>
    <collision>
      <origin rpy="0 0 0" xyz="0.095 -0.0 -0.04"/>
      <geometry>
        <mesh filename="../meshes/right_hip_main_link_1.stl" scale="0.001 0.001 0.001"/>
      </geometry>
    </collision>
  </link>
  <link name="left_hip_main_link_1">
    <inertial>
      <origin rpy="0 0 0" xyz="0.005000000000001184 2.973807334878842e-05 -0.054554354227767186"/>
      <mass value="0.06745093371390704"/>
      <inertia ixx="0.00017" ixy="-0.0" ixz="0.0" iyy="0.000162" iyz="-0.0" izz="9e-06"/>
    </inertial>
    <visual>
      <origin rpy="0 0 0" xyz="-0.095 -0.0 -0.04"/>
      <geometry>
        <mesh filename="../meshes/left_hip_main_link_1.stl" scale="0.001 0.001 0.001"/>
      </geometry>
      <material name="silver"/>
    </visual>
    <collision>
      <origin rpy="0 0 0" xyz="-0.095 -0.0 -0.04"/>
      <geometry>
        <mesh filename="../meshes/left_hip_main_link_1.stl" scale="0.001 0.001 0.001"/>
      </geometry>
    </collision>
  </link>
  <joint name="left_knee_joint" type="continuous">
    <origin rpy="0 0 0" xyz="0.01 0.0 -0.149"/>
    <parent link="left_hip_main_link_1"/>
    <child link="left_leg_link_1"/>
    <axis xyz="-1.0 0.0 0.0"/>
  </joint>
  <joint name="right_knee_joint" type="continuous">
    <origin rpy="0 0 0" xyz="-0.01 -0.0 -0.149"/>
    <parent link="right_hip_main_link_1"/>
    <child link="right_leg_link_1"/>
    <axis xyz="-1.0 0.0 0.0"/>
  </joint>
  <joint name="right_wheel_joint" type="continuous">
    <origin rpy="0 0 0" xyz="-0.01 7e-06 -0.133"/>
    <parent link="right_leg_link_1"/>
    <child link="right_wheel_1"/>
    <axis xyz="1.0 0.0 0.0"/>
  </joint>
  <joint name="left_wheel_joint" type="continuous">
    <origin rpy="0 0 0" xyz="0.01 7e-06 -0.133"/>
    <parent link="left_leg_link_1"/>
    <child link="left_wheel_1"/>
    <axis xyz="1.0 0.0 0.0"/>
  </joint>
  <joint name="right_hip_joint" type="continuous">
    <origin rpy="0 0 0" xyz="-0.095 0.0 0.04"/>
    <parent link="base_link"/>
    <child link="right_hip_main_link_1"/>
    <axis xyz="1.0 0.0 0.0"/>
  </joint>
  <joint name="left_hip_joint" type="continuous">
    <origin rpy="0 0 0" xyz="0.095 0.0 0.04"/>
    <parent link="base_link"/>
    <child link="left_hip_main_link_1"/>
    <axis xyz="1.0 0.0 0.0"/>
  </joint>
</robot>
